Workbook

Sheet Overall - Summary 
A1: Summary of Documents | O1: =TODAY() -> 46266
B2: ACONEX STATUS | M2: TOTAL SUBMISSION & PERCENTAGE (ACONEX)
A3: Documents Type & Discipline | B3: Under Review | C3: A - Work May Proceed | D3: B- Incorporate Comments - Proceed | E3: C - Revise and Resubmit - Do Not Proceed | F3: D - Rejected | G3: E - Review not Required - Proceed | H3: For Review & Approval | I3: Open | J3: Closed | K3: Terminate | L3: Cancelled | M3: Cumulative/Actual | N3: Total - Documents | O3: Approved % Code A, B & E
A4: CIV - MAT | B4: ='CIV - MAT'!G6 -> 1 | C4: ='CIV - MAT'!B6 -> 49 | D4: ='CIV - MAT'!C6 -> 8 | E4: ='CIV - MAT'!D6 -> 0 | F4: ='CIV - MAT'!E6 -> 1 | G4: ='CIV - MAT'!F6 -> 0 | H4: ='CIV - MAT'!H6 -> 0 | K4: ='CIV - MAT'!I6 -> 0 | L4: ='CIV - MAT'!J6 -> 31 | M4: =SUM(B4:J4) -> 59 | N4: =SUM(B4:L4) -> 90 | O4: =(C4+D4+G4)/M4 -> 0.96610169
A5: STR - MAT | B5: ='STR - MAT'!G6 -> 0 | C5: ='STR - MAT'!B6 -> 13 | D5: ='STR - MAT'!C6 -> 5 | E5: ='STR - MAT'!D6 -> 1 | F5: ='STR - MAT'!E6 -> 0 | G5: ='STR - MAT'!F6 -> 0 | H5: ='STR - MAT'!H6 -> 0 | K5: ='STR - MAT'!I6 -> 0 | L5: ='STR - MAT'!J6 -> 3 | M5: =SUM(B5:J5) -> 19 | N5: =SUM(B5:L5) -> 22 | O5: =(C5+D5+G5)/M5 -> 0.94736842
A6: ELE - MAT | B6: ='ELE - MAT'!G6 -> 1 | C6: ='ELE - MAT'!B6 -> 34 | D6: ='ELE - MAT'!C6 -> 2 | E6: ='ELE - MAT'!D6 -> 2 | F6: ='ELE - MAT'!E6 -> 0 | G6: ='ELE - MAT'!F6 -> 0 | H6: ='ELE - MAT'!H6 -> 1 | K6: ='ELE - MAT'!I6 -> 0 | L6: ='ELE - MAT'!J6 -> 21 | M6: =SUM(B6:J6) -> 40 | N6: =SUM(B6:L6) -> 61 | O6: =(C6+D6+G6)/M6 -> 0.9
A7: ARC- MAT | B7: ='ARC - MAT'!G6 -> 6 | C7: ='ARC - MAT'!B6 -> 70 | D7: ='ARC - MAT'!C6 -> 5 | E7: ='ARC - MAT'!D6 -> 8 | F7: ='ARC - MAT'!E6 -> 0 | G7: ='ARC - MAT'!F6 -> 0 | H7: ='ARC - MAT'!H6 -> 0 | K7: ='ARC - MAT'!I6 -> 0 | L7: ='ARC - MAT'!J6 -> 44 | M7: =SUM(B7:J7) -> 89 | N7: =SUM(B7:L7) -> 133 | O7: =(C7+D7+G7)/M7 -> 0.84269663
A8: MEC- MAT | B8: ='MEC- MAT'!G6 -> 10 | C8: ='MEC- MAT'!B6 -> 86 | D8: ='MEC- MAT'!C6 -> 13 | E8: ='MEC- MAT'!D6 -> 5 | F8: ='MEC- MAT'!E6 -> 0 | G8: ='MEC- MAT'!F6 -> 0 | H8: ='MEC- MAT'!H6 -> 0 | K8: ='MEC- MAT'!I6 -> 0 | L8: ='MEC- MAT'!J6 -> 21 | M8: =SUM(B8:J8) -> 114 | N8: =SUM(B8:L8) -> 135 | O8: =(C8+D8+G8)/M8 -> 0.86842105
A9: SEC- MAT | B9: ='SEC- MAT'!G6 -> 0 | C9: ='SEC- MAT'!B6 -> 1 | D9: ='SEC- MAT'!C6 -> 1 | E9: ='SEC- MAT'!D6 -> 0 | F9: ='SEC- MAT'!E6 -> 0 | G9: ='SEC- MAT'!F6 -> 0 | H9: ='SEC- MAT'!H6 -> 0 | K9: ='SEC- MAT'!I6 -> 0 | L9: ='SEC- MAT'!J6 -> 2 | M9: =SUM(B9:J9) -> 2 | N9: =SUM(B9:L9) -> 4 | O9: =(C9+D9+G9)/M9 -> 1
A10: FPR - MAT | B10: ='FPR - MAT'!G6 -> 1 | C10: ='FPR - MAT'!B6 -> 1 | D10: ='FPR - MAT'!C6 -> 0 | E10: ='FPR - MAT'!D6 -> 0 | F10: ='FPR - MAT'!E6 -> 0 | G10: ='FPR - MAT'!F6 -> 0 | H10: ='FPR - MAT'!H6 -> 0 | K10: ='FPR - MAT'!I6 -> 0 | L10: ='FPR - MAT'!J6 -> 0 | M10: =SUM(B10:J10) -> 2 | N10: =SUM(B10:L10) -> 2 | O10: =(C10+D10+G10)/M10 -> 0.5
A11: ICT - MAT | B11: ='ICT - MAT'!G6 -> 1 | C11: ='ICT - MAT'!B6 -> 2 | D11: ='ICT - MAT'!C6 -> 1 | E11: ='ICT - MAT'!D6 -> 0 | F11: ='ICT - MAT'!E6 -> 0 | G11: ='ICT - MAT'!F6 -> 0 | H11: ='ICT - MAT'!H6 -> 0 | K11: ='ICT - MAT'!I6 -> 0 | L11: ='ICT - MAT'!J6 -> 0 | M11: =SUM(B11:J11) -> 4 | N11: =SUM(B11:L11) -> 4 | O11: =(C11+D11+G11)/M11 -> 0.75
A12: LAN - MAT | B12: ='LAN - MAT'!G6 -> 0 | C12: ='LAN - MAT'!B6 -> 6 | D12: ='LAN - MAT'!C6 -> 5 | E12: ='LAN - MAT'!D6 -> 0 | F12: ='LAN - MAT'!E6 -> 0 | G12: ='LAN - MAT'!F6 -> 0 | H12: ='LAN - MAT'!H6 -> 0 | K12: ='LAN - MAT'!I6 -> 0 | L12: ='LAN - MAT'!J6 -> 2 | M12: =SUM(B12:J12) -> 11 | N12: =SUM(B12:L12) -> 13 | O12: =(C12+D12+G12)/M12 -> 1
A13: ELV - MAT | B13: ='ELV - MAT'!G6 -> 0 | C13: ='ELV - MAT'!B6 -> 9 | D13: ='ELV - MAT'!C6 -> 2 | E13: ='ELV - MAT'!D6 -> 0 | F13: ='ELV - MAT'!E6 -> 0 | G13: ='ELV - MAT'!F6 -> 0 | H13: ='ELV - MAT'!H6 -> 0 | K13: ='ELV - MAT'!I6 -> 0 | L13: ='ELV - MAT'!J6 -> 2 | M13: =SUM(B13:J13) -> 11 | N13: =SUM(B13:L13) -> 13 | O13: =(C13+D13+G13)/M13 -> 1
A14: Overall - Material Submittals é | B14: =SUM(B4:B13) -> 20 | C14: =SUM(C4:C13) -> 271 | D14: =SUM(D4:D13) -> 42 | E14: =SUM(E4:E13) -> 16 | F14: =SUM(F4:F13) -> 1 | G14: =SUM(G4:G13) -> 0 | H14: =SUM(H4:H13) -> 1 | K14: =SUM(K4:K13) -> 0 | L14: =SUM(L4:L13) -> 126 | M14: =SUM(M4:M13) -> 351 | N14: =SUM(N4:N13) -> 477 | O14: =(C14+D14+G14)/M14 -> 0.89173789
A15: CIV - PQD | B15: ='CIV - PQD'!G6 -> 1 | C15: ='CIV - PQD'!B6 -> 21 | D15: ='CIV - PQD'!C6 -> 0 | E15: ='CIV - PQD'!D6 -> 0 | F15: ='CIV - PQD'!E6 -> 0 | G15: ='CIV - PQD'!F6 -> 0 | H15: ='CIV - PQD'!H6 -> 0 | K15: ='CIV - PQD'!I6 -> 0 | L15: ='CIV - PQD'!J6 -> 2 | M15: =SUM(B15:J15) -> 22 | N15: =SUM(B15:L15) -> 24 | O15: =(C15+D15+G15)/M15 -> 0.95454545
A16: ELE - PQD | B16: ='ELE - PQD'!G6 -> 0 | C16: ='ELE - PQD'!B6 -> 32 | D16: ='ELE - PQD'!C6 -> 2 | E16: ='ELE - PQD'!D6 -> 0 | F16: ='ELE - PQD'!E6 -> 0 | G16: ='ELE - PQD'!F6 -> 1 | H16: ='ELE - PQD'!H6 -> 0 | K16: ='ELE - PQD'!I6 -> 0 | L16: ='ELE - PQD'!J6 -> 4 | M16: =SUM(B16:J16) -> 35 | N16: =SUM(B16:L16) -> 39 | O16: =(C16+D16+G16)/M16 -> 1
A17: MEC - PQD | B17: ='MEC - PQD'!G6 -> 1 | C17: ='MEC - PQD'!B6 -> 81 | D17: ='MEC - PQD'!C6 -> 5 | E17: ='MEC - PQD'!D6 -> 0 | F17: ='MEC - PQD'!E6 -> 1 | G17: ='MEC - PQD'!F6 -> 3 | H17: ='MEC - PQD'!H6 -> 0 | K17: ='MEC - PQD'!I6 -> 0 | L17: ='MEC - PQD'!J6 -> 8 | M17: =SUM(B17:J17) -> 91 | N17: =SUM(B17:L17) -> 99 | O17: =(C17+D17+G17)/M17 -> 0.97802198
A18: STR - PQD | B18: ='STR - PQD'!G6 -> 0 | C18: ='STR - PQD'!B6 -> 2 | D18: ='STR - PQD'!C6 -> 0 | E18: ='STR - PQD'!D6 -> 0 | F18: ='STR - PQD'!E6 -> 0 | G18: ='STR - PQD'!F6 -> 0 | H18: ='STR - PQD'!H6 -> 0 | K18: ='STR - PQD'!I6 -> 0 | L18: ='STR - PQD'!J6 -> 0 | M18: =SUM(B18:J18) -> 2 | N18: =SUM(B18:L18) -> 2 | O18: =(C18+D18+G18)/M18 -> 1
A19: ARC - PQD | B19: ='ARC - PQD'!G6 -> 0 | C19: ='ARC - PQD'!B6 -> 27 | D19: ='ARC - PQD'!C6 -> 1 | E19: ='ARC - PQD'!D6 -> 0 | F19: ='ARC - PQD'!E6 -> 0 | G19: ='ARC - PQD'!F6 -> 0 | H19: ='ARC - PQD'!F6 -> 0 | K19: ='ARC - PQD'!I6 -> 0 | L19: ='ARC - PQD'!J6 -> 1 | M19: =SUM(B19:J19) -> 28 | N19: =SUM(B19:L19) -> 29 | O19: =(C19+D19+G19)/M19 -> 1
A20: FLS - PQD | B20: ='FLS - PQD'!G6 -> 0 | C20: ='FLS - PQD'!B6 -> 1 | D20: ='FLS - PQD'!C6 -> 1 | E20: ='FLS - PQD'!D6 -> 0 | F20: ='FLS - PQD'!E6 -> 0 | G20: ='FLS - PQD'!F6 -> 0 | H20: ='FLS - PQD'!H6 -> 0 | K20: ='FLS - PQD'!I6 -> 0 | L20: ='FLS - PQD'!J6 -> 1 | M20: =SUM(B20:J20) -> 2 | N20: =SUM(B20:L20) -> 3 | O20: =(C20+D20+G20)/M20 -> 1
A21: SEC - PQD | B21: ='SEC - PQD'!G6 -> 0 | C21: ='SEC - PQD'!B6 -> 3 | D21: ='SEC - PQD'!C6 -> 0 | E21: ='SEC - PQD'!D6 -> 0 | F21: ='SEC - PQD'!E6 -> 0 | G21: ='SEC - PQD'!F6 -> 1 | H21: ='SEC - PQD'!H6 -> 0 | K21: ='SEC - PQD'!I6 -> 0 | L21: ='SEC - PQD'!J6 -> 1 | M21: =SUM(B21:J21) -> 4 | N21: =SUM(B21:L21) -> 5 | O21: =(C21+D21+G21)/M21 -> 1
A22: SUS - PQD | B22: ='SUS - PQD'!G6 -> 0 | C22: ='SUS - PQD'!B6 -> 1 | D22: ='SUS - PQD'!C6 -> 0 | E22: ='SUS - PQD'!D6 -> 0 | F22: ='SUS - PQD'!E6 -> 0 | G22: ='SUS - PQD'!F6 -> 0 | H22: ='SUS - PQD'!H6 -> 0 | K22: ='SUS - PQD'!I6 -> 0 | L22: ='SUS - PQD'!J6 -> 2 | M22: =SUM(B22:J22) -> 1 | N22: =SUM(B22:L22) -> 3 | O22: =(C22+D22+G22)/M22 -> 1
A23: Overall - Prequalification Document é | B23: =SUM(B15:B22) -> 2 | C23: =SUM(C15:C22) -> 168 | D23: =SUM(D15:D22) -> 9 | E23: =SUM(E15:E22) -> 0 | F23: =SUM(F15:F22) -> 1 | G23: =SUM(G15:G22) -> 5 | H23: =SUM(H15:H22) -> 0 | K23: =SUM(K15:K22) -> 0 | L23: =SUM(L15:L22) -> 19 | M23: =SUM(M15:M22) -> 185 | N23: =SUM(N15:N22) -> 204 | O23: =(C23+D23+G23)/M23 -> 0.98378378
A24: CIV - MST | B24: ='CIV - MST'!G6 -> 1 | C24: ='CIV - MST'!B6 -> 32 | D24: ='CIV - MST'!C6 -> 0 | E24: ='CIV - MST'!D6 -> 0 | F24: ='CIV - MST'!E6 -> 0 | G24: ='CIV - MST'!F6 -> 0 | H24: ='CIV - MST'!H6 -> 0 | K24: ='CIV - MST'!I6 -> 0 | L24: ='CIV - MST'!J6 -> 10 | M24: =SUM(B24:J24) -> 33 | N24: =SUM(B24:L24) -> 43 | O24: =(C24+D24+G24)/M24 -> 0.96969697
A25: STR - MST | B25: ='STR - MST'!G6 -> 0 | C25: ='STR - MST'!B6 -> 9 | D25: ='STR - MST'!C6 -> 0 | E25: ='STR - MST'!D6 -> 0 | F25: ='STR - MST'!E6 -> 0 | G25: ='STR - MST'!F6 -> 0 | H25: ='STR - MST'!H6 -> 0 | K25: ='STR - MST'!I6 -> 0 | L25: ='STR - MST'!J6 -> 0 | M25: =SUM(B25:J25) -> 9 | N25: =SUM(B25:L25) -> 9 | O25: =(C25+D25+G25)/M25 -> 1
A26: ARC- MST | B26: ='ARC- MST'!G6 -> 0 | C26: ='ARC- MST'!B6 -> 18 | D26: ='ARC- MST'!C6 -> 1 | E26: ='ARC- MST'!D6 -> 0 | F26: ='ARC- MST'!E6 -> 0 | G26: ='ARC- MST'!F6 -> 0 | H26: ='ARC- MST'!H6 -> 0 | K26: ='ARC- MST'!I6 -> 0 | L26: ='ARC- MST'!J6 -> 1 | M26: =SUM(B26:J26) -> 19 | N26: =SUM(B26:L26) -> 20 | O26: =(C26+D26+G26)/M26 -> 1
A27: SRV - MST | B27: ='SRV - MST'!G6 -> 0 | C27: ='SRV - MST'!B6 -> 1 | D27: ='SRV - MST'!C6 -> 0 | E27: ='SRV - MST'!D6 -> 0 | F27: ='SRV - MST'!E6 -> 0 | G27: ='SRV - MST'!F6 -> 0 | H27: ='SRV - MST'!H6 -> 0 | K27: ='SRV - MST'!I6 -> 0 | L27: ='SRV - MST'!J6 -> 1 | M27: =SUM(B27:J27) -> 1 | N27: =SUM(B27:L27) -> 2 | O27: =(C27+D27+G27)/M27 -> 1
A28: MEC - MST | B28: ='MEC - MST'!G6 -> 0 | C28: ='MEC - MST'!B6 -> 18 | D28: ='MEC - MST'!C6 -> 1 | E28: ='MEC - MST'!D6 -> 1 | F28: ='MEC - MST'!E6 -> 0 | G28: ='MEC - MST'!F6 -> 0 | H28: ='MEC - MST'!H6 -> 1 | K28: ='MEC - MST'!I6 -> 0 | L28: ='MEC - MST'!J6 -> 2 | M28: =SUM(B28:J28) -> 21 | N28: =SUM(B28:L28) -> 23 | O28: =(C28+D28+G28)/M28 -> 0.9047619
A29: ELE - MST | B29: ='ELE - MST'!G6 -> 0 | C29: ='ELE - MST'!B6 -> 14 | D29: ='ELE - MST'!C6 -> 1 | E29: ='ELE - MST'!D6 -> 0 | F29: ='ELE - MST'!E6 -> 0 | G29: ='ELE - MST'!F6 -> 0 | H29: ='ELE - MST'!H6 -> 0 | K29: ='ELE - MST'!I6 -> 0 | L29: ='ELE - MST'!J6 -> 2 | M29: =SUM(B29:J29) -> 15 | N29: =SUM(B29:L29) -> 17 | O29: =(C29+D29+G29)/M29 -> 1
A30: ELV - MST | B30: ='ELV - MST'!G6 -> 0 | C30: ='ELV - MST'!B6 -> 8 | D30: ='ELV - MST'!C6 -> 0 | E30: ='ELV - MST'!D6 -> 0 | F30: ='ELV - MST'!E6 -> 0 | G30: ='ELV - MST'!F6 -> 0 | H30: ='ELV - MST'!H6 -> 0 | K30: ='ELV - MST'!I6 -> 0 | L30: ='ELV - MST'!J6 -> 0 | M30: =SUM(B30:J30) -> 8 | N30: =SUM(B30:L30) -> 8 | O30: =(C30+D30+G30)/M30 -> 1
A31: INF - MST | B31: ='INF - MST '!G6 -> 2 | C31: ='INF - MST '!B6 -> 2 | D31: ='INF - MST '!C6 -> 0 | E31: ='INF - MST '!D6 -> 1 | F31: ='INF - MST '!E6 -> 0 | G31: ='INF - MST '!F6 -> 0 | H31: ='INF - MST '!H6 -> 0 | K31: ='INF - MST '!I6 -> 0 | L31: ='INF - MST '!J6 -> 0 | M31: =SUM(B31:J31) -> 5 | N31: =SUM(B31:L31) -> 5 | O31: =(C31+D31+G31)/M31 -> 0.4
A32: GEO - MST | B32: ='GEO - MST'!G6 -> 0 | C32: ='GEO - MST'!B6 -> 0 | D32: ='GEO - MST'!C6 -> 0 | E32: ='GEO - MST'!D6 -> 0 | F32: ='GEO - MST'!E6 -> 0 | G32: ='GEO - MST'!F6 -> 0 | H32: ='GEO - MST'!H6 -> 0 | K32: ='GEO - MST'!I6 -> 0 | L32: ='GEO - MST'!J6 -> 1 | M32: =SUM(B32:J32) -> 0 | N32: =SUM(B32:L32) -> 1 | O32: =(C32+D32+G32)/M32 -> #DIV/0!
A33: CON - MST | B33: ='CON - MST'!G6 -> 0 | C33: ='CON - MST'!B6 -> 0 | D33: ='CON - MST'!C6 -> 0 | E33: ='CON - MST'!D6 -> 0 | F33: ='CON - MST'!E6 -> 0 | G33: ='CON - MST'!F6 -> 0 | H33: ='CON - MST'!H6 -> 0 | K33: ='CON - MST'!I6 -> 0 | L33: ='CON - MST'!J6 -> 1 | M33: =SUM(B33:J33) -> 0 | N33: =SUM(B33:L33) -> 1 | O33: =(C33+D33+G33)/M33 -> #DIV/0!
A34: HSE - MST | B34: ='HSE - MST'!G6 -> 0 | C34: ='HSE - MST'!B6 -> 6 | D34: ='HSE - MST'!C6 -> 0 | E34: ='HSE - MST'!D6 -> 0 | F34: ='HSE - MST'!E6 -> 0 | G34: ='HSE - MST'!F6 -> 0 | H34: ='HSE - MST'!H6 -> 0 | K34: ='HSE - MST'!I6 -> 0 | L34: ='HSE - MST'!J6 -> 1 | M34: =SUM(B34:J34) -> 6 | N34: =SUM(B34:L34) -> 7 | O34: =(C34+D34+G34)/M34 -> 1
A35: Overall - Method Statement é | B35: =SUM(B24:B34) -> 3 | C35: =SUM(C24:C34) -> 108 | D35: =SUM(D24:D34) -> 3 | E35: =SUM(E24:E34) -> 2 | F35: =SUM(F24:F34) -> 0 | G35: =SUM(G24:G34) -> 0 | H35: =SUM(H24:H34) -> 1 | K35: =SUM(K24:K34) -> 0 | L35: =SUM(L24:L34) -> 19 | M35: =SUM(M24:M34) -> 117 | N35: =SUM(N24:N34) -> 136 | O35: =(C35+D35+G35)/M35 -> 0.94871795
A36: CIV - ITP | B36: ='CIV - ITP'!G6 -> 0 | C36: ='CIV - ITP'!B6 -> 12 | D36: ='CIV - ITP'!C6 -> 0 | E36: ='CIV - ITP'!D6 -> 0 | F36: ='CIV - ITP'!E6 -> 0 | G36: ='CIV - ITP'!F6 -> 0 | H36: ='CIV - ITP'!H6 -> 0 | K36: ='CIV - ITP'!I6 -> 0 | L36: ='CIV - ITP'!J6 -> 7 | M36: =SUM(B36:J36) -> 12 | N36: =SUM(B36:L36) -> 19 | O36: =(C36+D36+G36)/M36 -> 1
A37: STR - ITP | B37: ='STR - ITP'!G6 -> 0 | C37: ='STR - ITP'!B6 -> 4 | D37: ='STR - ITP'!C6 -> 0 | E37: ='STR - ITP'!D6 -> 0 | F37: ='STR - ITP'!E6 -> 0 | G37: ='STR - ITP'!F6 -> 0 | H37: ='STR - ITP'!H6 -> 0 | K37: ='STR - ITP'!I6 -> 0 | L37: ='STR - ITP'!J6 -> 0 | M37: =SUM(B37:J37) -> 4 | N37: =SUM(B37:L37) -> 4 | O37: =(C37+D37+G37)/M37 -> 1
A38: ARC - ITP | B38: ='ARC - ITP '!G6 -> 0 | C38: ='ARC - ITP '!B6 -> 17 | D38: ='ARC - ITP '!C6 -> 0 | E38: ='ARC - ITP '!D6 -> 0 | F38: ='ARC - ITP '!E6 -> 0 | G38: ='ARC - ITP '!F6 -> 0 | H38: ='ARC - ITP '!H6 -> 0 | K38: ='ARC - ITP '!I6 -> 0 | L38: ='ARC - ITP '!J6 -> 0 | M38: =SUM(B38:J38) -> 17 | N38: =SUM(B38:L38) -> 17 | O38: =(C38+D38+G38)/M38 -> 1
A39: SRV - ITP | B39: ='SRV - ITP'!G6 -> 0 | C39: ='SRV - ITP'!B6 -> 0 | D39: ='SRV - ITP'!C6 -> 0 | E39: ='SRV - ITP'!D6 -> 0 | F39: ='SRV - ITP'!E6 -> 0 | G39: ='SRV - ITP'!F6 -> 1 | H39: ='SRV - ITP'!H6 -> 0 | K39: ='SRV - ITP'!I6 -> 0 | L39: ='SRV - ITP'!J6 -> 0 | M39: =SUM(B39:J39) -> 1 | N39: =SUM(B39:L39) -> 1 | O39: =(C39+D39+G39)/M39 -> 1
A40: INF - ITP | B40: ='INF - ITP'!G6 -> 0 | C40: ='INF - ITP'!B6 -> 1 | D40: ='INF - ITP'!C6 -> 0 | E40: ='INF - ITP'!D6 -> 0 | F40: ='INF - ITP'!E6 -> 0 | G40: ='INF - ITP'!F6 -> 0 | H40: ='INF - ITP'!H6 -> 0 | K40: ='INF - ITP'!I6 -> 0 | L40: ='INF - ITP'!J6 -> 0 | M40: =SUM(B40:J40) -> 1 | N40: =SUM(B40:L40) -> 1 | O40: =(C40+D40+G40)/M40 -> 1
...

Sheet CIV - MAT
B1: Contract Title: | C1: 4800001272-FHD-Construction of OXAGON Coast Guard Facilities | I1: Date: | J1: =TODAY() -> 46266
B2: Type of Doc: | C2: Material Submittal (MAT)
B3: Discipline: | C3: CIV - Civil
B5: A - Work May Proceed | C5: B- Incorporate Comments - Proceed | D5: C - Revise and Resubmit - Do Not Proceed | E5: D - Rejected | F5: E - Review not Required - Proceed | G5: UR | H5: For Approval | I5: Terminated | J5: Cancelled
B6: =COUNTIF(B11:B102,"A - Work May Proceed") -> 49 | C6: =COUNTIF(B11:B102,"B- Incorporate Comments - Proceed") -> 8 | D6: =COUNTIF(B11:B102,"C - Revise and Resubmit - Do Not Proceed") -> 0 | E6: =COUNTIF(B11:B102,"D - Rejected") -> 1 | F6: =COUNTIF(B11:B102,"E - Review not Required - Proceed") -> 0 | G6: =COUNTIF(B11:B102,"UR") -> 1 | H6: =COUNTIF(B11:B102,"FA") -> 0 | I6: =COUNTIF(B11:B102,"Terminated") -> 0 | J6: =COUNTIF(B11:B102,"Cancelled") -> 31
B8: TOTAL | C8: =SUM(B6:J6) -> 90
A10: Asset Codes | B10: Current - Status | C10: Current - Revision | D10: ACONEX Document No | E10: Comments Resolution Sheet (CRS) | F10: Title | G10: Type | H10: Discipline | I10: Revision _ 01 - History | P10: Revision _ 02 - History | W10: Revision _ 03 - History | AD10: Revision _ 04 - History | AK10: Revision _ 05 - History | AR10: Revision _ 06 - History | AY10: Revision _ 07 - History | BF10: Internal notes
I11: Status | J11: Submission Date | K11: Al-Fahd Transmittal Reference | L11: Expected of Response | M11: Receiving Date | N11: Delay of Days | O11: Workflow Transmittal | P11: Status | Q11: Submission Date | R11: Al-Fahd Transmittal Reference | S11: Expected of Response | T11: Receiving Date | U11: Delay of Days | V11: Workflow Transmittal | W11: Status | X11: Submission Date | Y11: Al-Fahd Transmittal Reference | Z11: Expected of Response | AA11: Receiving Date | AB11: Delay of Days | AC11: Workflow Transmittal | AD11: Status | AE11: Submission Date | AF11: Al-Fahd Transmittal Reference | AG11: Expected of Response | AH11: Receiving Date | AI11: Delay of Days | AJ11: Workflow Transmittal | AK11: Status | AL11: Submission Date | AM11: Al-Fahd Transmittal Reference | AN11: Expected of Response | AO11: Receiving Date | AP11: Delay of Days | AQ11: Workflow Transmittal | AR11: Status | AS11: Submission Date | AT11: Al-Fahd Transmittal Reference | AU11: Expected of Response | AV11: Receiving Date | AW11: Delay of Days | AX11: Workflow Transmittal | AY11: Status | AZ11: Submission Date | BA11: Al-Fahd Transmittal Reference | BB11: Expected of Response | BC11: Receiving Date | BD11: Delay of Days | BE11: Workflow Transmittal
A12: 730007 | B12: A - Work May Proceed | C12: 03 | D12: 40-730007-4800001272-FHD-CIV-MAT-000001 | E12: 40-730007-4800001272-FHD-CIV-CRS-000001 | F12: 4800001272/000 - Material submittal for Curing Compound by Sika Saudi Arabia | G12: Material Submittal | H12: CIV - Civil | I12: B- Incorporate Comments - Proceed | J12: 45554 | K12: FHD-TRANSMIT-000002 | L12: =J12+7 -> 45561 | M12: 45561 | N12: =M12-L12 -> 0 | O12: WF-000231 | P12: B- Incorporate Comments - Proceed | Q12: 46195 | R12: FHD-TRANSMIT-005761 | S12: =Q12+7 -> 46202 | T12: 46198 | U12: =T12-S12 -> -4 | V12: WF-025223 | W12: A - Work May Proceed | X12: 46201 | Y12: FHD-TRANSMIT-005831 | Z12: =X12+7 -> 46208 | AA12: 46201 | AB12: =AA12-Z12 -> -7 | AC12: WF-025500
A13: 730007 | B13: Cancelled | C13: XX | D13: 40-730007-4800001272-FHD-CIV-MAT-000002 | E13: 40-730007-4800001272-FHD-CIV-CRS-000002 | F13: 4800001272-FHD-CG - Material Submittal for Bitumen Emulsion Damp-Proofing & Protective Coating - Sika®-Bitumen-60. | G13: Material Submittal | H13: CIV - Civil | I13: B- Incorporate Comments - Proceed | J13: 45554 | K13: FHD-TRANSMIT-000004 | L13: =J13+7 -> 45561 | M13: 45561 | N13: =M13-L13 -> 0 | O13: WF-000232 | P13: Cancelled | Q13: 46233 | R13: FHD-TRANSMIT-006157
A14: 730007 | B14: A - Work May Proceed | C14: 02 | D14: 40-730007-4800001272-FHD-CIV-MAT-000003 | E14: 40-730007-4800001272-FHD-CIV-CRS-000003 | F14: 4800001272-FHD-CG - Material Submittal for Bonding Agent and Mortar Admixture - Sika Bond®DV. | G14: Material Submittal | H14: CIV - Civil | I14: B- Incorporate Comments - Proceed | J14: 45554 | K14: FHD-TRANSMIT-000005 | L14: =J14+7 -> 45561 | M14: 45561 | N14: =M14-L14 -> 0 | O14: WF-000233 | P14: A - Work May Proceed | Q14: 46195 | R14: FHD-TRANSMIT-005770 | S14: =Q14+7 -> 46202 | T14: 46201 | U14: =T14-S14 -> -1 | V14: WF-025281
A15: 730007 | B15: A - Work May Proceed | C15: 02 | D15: 40-730007-4800001272-FHD-CIV-MAT-000004 | E15: 40-730007-4800001272-FHD-CIV-CRS-000004 | F15: 4800001272-FHD-CG - Material Submittal for Anti-Corrosive Shutter Release Agent - Sika®Mould BA. | G15: Material Submittal | H15: CIV - Civil | I15: B- Incorporate Comments - Proceed | J15: 45554 | K15: FHD-TRANSMIT-000006 | L15: =J15+7 -> 45561 | M15: 45561 | N15: =M15-L15 -> 0 | O15: WF-000234 | P15: A - Work May Proceed | Q15: 46195 | R15: FHD-TRANSMIT-005767 | S15: =Q15+7 -> 46202 | T15: 46201 | U15: =T15-S15 -> -1 | V15: WF-025360
A16: 730007 | B16: Cancelled | C16: XX | D16: 40-730007-4800001272-FHD-CIV-MAT-000005 | E16: 40-730007-4800001272-FHD-CIV-CRS-000005 | F16: 4800001272-FHD-CG - Material Submittal for Flexible Sealant for Concrete and Precast Joints - Sikaflex® Construction+ | G16: Material Submittal | H16: CIV - Civil | I16: B- Incorporate Comments - Proceed | J16: 45554 | K16: FHD-TRANSMIT-000007 | L16: =J16+7 -> 45561 | M16: 45561 | N16: =M16-L16 -> 0 | O16: WF-000235 | P16: Cancelled | Q16: 46196 | R16: FHD-TRANSMIT-005778 | S16: _ | T16: _ | U16: _ | V16: _
A17: 730007 | B17: Cancelled | C17: XX | D17: 40-730007-4800001272-FHD-CIV-MAT-000006 | E17: 40-730007-4800001272-FHD-CIV-CRS-000006 | F17: 4800001272-FHD-CG - Material Submittal for High Performance Civil Engineering Joint Sealant - Sikaflex® PRO-3 | G17: Material Submittal | H17: CIV - Civil | I17: B- Incorporate Comments - Proceed | J17: 45554 | K17: FHD-TRANSMIT-000008 | L17: =J17+7 -> 45561 | M17: 45561 | N17: =M17-L17 -> 0 | O17: WF-000236 | P17: Cancelled | Q17: 46196 | R17: FHD-TRANSMIT-005778 | S17: _ | T17: _ | U17: _ | V17: _
A18: 730007 | B18: A - Work May Proceed | C18: 02 | D18: 40-730007-4800001272-FHD-CIV-MAT-000007 | E18: 40-730007-4800001272-FHD-CIV-CRS-000007 | F18: 4800001272-FHD-CG - Material Submittal for Cementitious, Shrinkage Compensated General Purpose Grout - SikaGrout® -114 SA | G18: Material Submittal | H18: CIV - Civil | I18: B- Incorporate Comments - Proceed | J18: 45554 | K18: FHD-TRANSMIT-000009 | L18: =J18+7 -> 45561 | M18: 45563 | N18: =M18-L18 -> 2 | O18: WF-000237 | P18: A - Work May Proceed | Q18: 46195 | R18: FHD-TRANSMIT-005768 | S18: =Q18+7 -> 46202 | T18: 46198 | U18: =T18-S18 -> -4 | V18: WF-025282
A19: 730007 | B19: A - Work May Proceed | C19: 03 | D19: 40-730007-4800001272-FHD-CIV-MAT-000008 | E19: 40-730007-4800001272-FHD-CIV-CRS-000008 | F19: 4800001272-FHD-CG - Material Submittal for Sealer, Finishing Mortar SikaRep® Fine SA | G19: Material Submittal | H19: CIV - Civil | I19: B- Incorporate Comments - Proceed | J19: 45554 | K19: FHD-TRANSMIT-000010 | L19: =J19+7 -> 45561 | M19: 45563 | N19: =M19-L19 -> 2 | O19: WF-000238 | P19: B- Incorporate Comments - Proceed | Q19: 46203 | R19: FHD-TRANSMIT-005867 | S19: =Q19+7 -> 46210 | T19: 46209 | U19: =T19-S19 -> -1 | V19: WF-025656 | W19: A - Work May Proceed | X19: 46210 | Y19: FHD-TRANSMIT-005952 | Z19: =X19+7 -> 46217 | AA19: 46225 | AB19: =AA19-Z19 -> 8 | AC19: WF-026140
A20: 730007 | B20: A - Work May Proceed | C20: 03 | D20: 40-730007-4800001272-FHD-CIV-MAT-000009 | E20: 40-730007-4800001272-FHD-CIV-CRS-000009 | F20: 4800001272-FHD-CG - Material Submittal for Multi-Purpose, Economical, Patching and Repair Mortar - SikaRep® SA | G20: Material Submittal | H20: CIV - Civil | I20: B- Incorporate Comments - Proceed | J20: 45554 | K20: FHD-TRANSMIT-000011 | L20: =J20+7 -> 45561 | M20: 45563 | N20: =M20-L20 -> 2 | O20: WF-000239 | P20: B- Incorporate Comments - Proceed | Q20: 46203 | R20: FHD-TRANSMIT-005876 | S20: =Q20+7 -> 46210 | T20: 46211 | U20: =T20-S20 -> 1 | V20: WF-025725 | W20: A - Work May Proceed | X20: 46211 | Y20: FHD-TRANSMIT-005963 | Z20: =X20+7 -> 46218 | AA20: 46225 | AB20: =AA20-Z20 -> 7 | AC20: WF-026199
A21: 730007 | B21: A - Work May Proceed | C21: 02 | D21: 40-730007-4800001272-FHD-CIV-MAT-000010 | E21: 40-730007-4800001272-FHD-CIV-CRS-000010 | F21: 4800001272-FHD-CG - Material Submittal for Hydrophilic Swellable Joint Sealing Profiles - SikaSwell® A | G21: Material Submittal | H21: CIV - Civil | I21: B- Incorporate Comments - Proceed | J21: 45554 | K21: FHD-TRANSMIT-000012 | L21: =J21+7 -> 45561 | M21: 45563 | N21: =M21-L21 -> 2 | O21: WF-000240 | P21: A - Work May Proceed | Q21: 46202 | R21: FHD-TRANSMIT-005857 | S21: =Q21+7 -> 46209 | T21: 46208 | U21: =T21-S21 -> -1 | V21: WF-025646
A22: 730007 | B22: A - Work May Proceed | C22: 03 | D22: 40-730007-4800001272-FHD-CIV-MAT-000011 | E22: 40-730007-4800001272-FHD-CIV-CRS-000011 | F22: 4800001272-FHD-CG - Material Submittal for Adhesive & Repair Motar-Thixotropic Epoxy Adhesive - Sikadur®-31 CF Slow | G22: Material Submittal | H22: CIV - Civil | I22: B- Incorporate Comments - Proceed | J22: 45554 | K22: FHD-TRANSMIT-000013 | L22: =J22+7 -> 45561 | M22: 45563 | N22: =M22-L22 -> 2 | O22: WF-000241 | P22: B- Incorporate Comments - Proceed | Q22: 46217 | R22: FHD-TRANSMIT-006038 | S22: =Q22+7 -> 46224 | T22: 46229 | U22: =T22-S22 -> 5 | V22: WF-026522 | W22: A - Work May Proceed | X22: 46229 | Y22: FHD-TRANSMIT-006117 | Z22: =X22+7 -> 46236 | AA22: 46233 | AB22: =AA22-Z22 -> -3 | AC22: WF-027178
A23: 730007 | B23: A - Work May Proceed | C23: 02 | D23: 40-730007-4800001272-FHD-CIV-MAT-000012 | E23: 40-730007-4800001272-FHD-CIV-CRS-000012 | F23: 4800001272-FHD-CG - Material Submittal for Concrete Crack Repairing Low Viscosity Injection Resin - Sikadur®-52 LP | G23: Material Submittal | H23: CIV - Civil | I23: B- Incorporate Comments - Proceed | J23: 45554 | K23: FHD-TRANSMIT-000014 | L23: =J23+7 -> 45561 | M23: 45563 | N23: =M23-L23 -> 2 | O23: WF-000242 | P23: A - Work May Proceed | Q23: 46055 | R23: FHD-TRANSMIT-004309 | S23: =Q23+7 -> 46062 | T23: 46056 | U23: =T23-S23 -> -6 | V23: WF-019045
A24: 730007 | B24: Cancelled | C24: 01 | D24: 40-730007-4800001272-FHD-CIV-MAT-000013 | E24: 40-730007-4800001272-FHD-CIV-CRS-000013 | F24: 4800001272-FHD-CG - Material Submittal for Smooth, Unicolour Conductive Epoxy Floor Covering - Sikafloor® MultiDur ES-24 ECF | G24: Material Submittal | H24: CIV - Civil | I24: B- Incorporate Comments - Proceed | J24: 45554 | K24: FHD-TRANSMIT-000015 | L24: =J24+7 -> 45561 | M24: 45563 | N24: =M24-L24 -> 2 | O24: WF-000243 | P24: Cancelled | Q24: 46233 | R24: FHD-TRANSMIT-006157
A25: 730007 | B25: A - Work May Proceed | C25: 03 | D25: 40-730007-4800001272-FHD-CIV-MAT-000014 | E25: 40-730007-4800001272-FHD-CIV-CRS-000014 | F25: 4800001272-FHD-CG - Material Submittal for Polyurethane-Based, Slightly Flexible, Foaming Injection Resin for the Permanent Watertight Sealing of Cracks - Sika® Injection-107 | G25: Material Submittal | H25: CIV - Civil | I25: B- Incorporate Comments - Proceed | J25: 45554 | K25: FHD-TRANSMIT-000016 | L25: =J25+7 -> 45561 | M25: 45563 | N25: =M25-L25 -> 2 | O25: WF-000244 | P25: C - Revise and Resubmit - Do Not Proceed | Q25: 46065 | R25: FHD-TRANSMIT-004452 | S25: =Q25+7 -> 46072 | T25: 46068 | U25: =T25-S25 -> -4 | V25: WF-019625 | W25: A - Work May Proceed | X25: 46116 | Y25: FHD-TRANSMIT-004899 | Z25: =X25+7 -> 46123 | AA25: 46116 | AB25: =AA25-Z25 -> -7 | AC25: WF-021630
A26: 730007 | B26: Cancelled | C26: XX | D26: 40-730007-4800001272-FHD-CIV-MAT-000015 | E26: 40-730007-4800001272-FHD-CIV-CRS-000018 | F26: 4800001272-FHD-CG - Material Submittal for Steel Bars by Rajhi Steel Industries Co. _ Supplier | G26: Material Submittal | H26: CIV - Civil | I26: C - Revise and Resubmit - Do Not Proceed | J26: 45554 | K26: FHD-TRANSMIT-000026 | L26: =J26+7 -> 45561 | M26: 45623 | N26: =M26-L26 -> 62 | O26: WF-000245 | P26: Cancelled | Q26: 45824 | R26: FHD-TRANSMIT-002165
A27: 730007 | B27: Cancelled | C27: XX | D27: 40-730007-4800001272-FHD-CIV-MAT-000016 | E27: 40-730007-4800001272-FHD-CIV-CRS-000019 | F27: 4800001272-FHD-CG - Material Submittal for Bituproof 320 Bituminous Damp Proofing by DCP Saudi Co. _ Supplier | G27: Material Submittal | H27: CIV - Civil | I27: B- Incorporate Comments - Proceed | J27: 45555 | K27: FHD-TRANSMIT-000027 | L27: =J27+7 -> 45562 | M27: 45564 | N27: =M27-L27 -> 2 | O27: WF-000246 | P27: Cancelled | Q27: 46196 | R27: FHD-TRANSMIT-005778 | S27: _ | T27: _ | U27: _ | V27: _
A28: 730007 | B28: Cancelled | C28: XX | D28: 40-730007-4800001272-FHD-CIV-MAT-000017 | E28: 40-730007-4800001272-FHD-CIV-CRS-000020 | F28: 4800001272-FHD-CG - Material Submittal for Flexseal PS660 High Performance two Component Polysulphide by DCP Saudi Co. _ Supplier | G28: Material Submittal | H28: CIV - Civil | I28: B- Incorporate Comments - Proceed | J28: 45555 | K28: FHD-TRANSMIT-000028 | L28: =J28+7 -> 45562 | M28: 45563 | N28: =M28-L28 -> 1 | O28: WF-000247 | P28: Cancelled | Q28: 46196 | R28: FHD-TRANSMIT-005778 | S28: _ | T28: _ | U28: _ | V28: _
A29: 730007 | B29: Cancelled | C29: XX | D29: 40-730007-4800001272-FHD-CIV-MAT-000018 | E29: 40-730007-4800001272-FHD-CIV-CRS-000021 | F29: 4800001272-FHD-CG - Material Submittal for Hydrostop AW PVC Waterstops by DCP Saudi Co. _ Supplier | G29: Material Submittal | H29: CIV - Civil | I29: B- Incorporate Comments - Proceed | J29: 45555 | K29: FHD-TRANSMIT-000029 | L29: =J29+7 -> 45562 | M29: 45561 | N29: =M29-L29 -> -1 | O29: WF-000248 | P29: Cancelled | Q29: 46196 | R29: FHD-TRANSMIT-005778 | S29: _ | T29: _ | U29: _ | V29: _
A30: 730007 | B30: A - Work May Proceed | C30: 02 | D30: 40-730007-4800001272-FHD-CIV-MAT-000019 | E30: 40-730007-4800001272-FHD-CIV-CRS-000022 | F30: 4800001272-FHD-CG - Material Submittal for Polyethylene Rolls Films - Vapor Barrier by Unitech for Building & Construction Materials _ Supplier | G30: Material Submittal | H30: CIV - Civil | I30: B- Incorporate Comments - Proceed | J30: 45555 | K30: FHD-TRANSMIT-000030 | L30: =J30+7 -> 45562 | M30: 45561 | N30: =M30-L30 -> -1 | O30: WF-000249 | P30: A - Work May Proceed | Q30: 46205 | R30: FHD-TRANSMIT-005896 | S30: =Q30+7 -> 46212 | T30: 46215 | U30: =T30-S30 -> 3 | V30: WF-025850
A31: 730007 | B31: Cancelled | C31: XX | D31: 40-730007-4800001272-FHD-CIV-MAT-000020 | E31: 40-730007-4800001272-FHD-CIV-CRS-000023 | F31: 4800001272-FHD-CG - Material Submittal for Keyfix E Epoxy Resin Cartridge System for Anchoring by DCP Saudi Co. _ Supplier | G31: Material Submittal | H31: CIV - Civil | I31: B- Incorporate Comments - Proceed | J31: 45555 | K31: FHD-TRANSMIT-000031 | L31: =J31+7 -> 45562 | M31: 45561 | N31: =M31-L31 -> -1 | O31: WF-000250 | P31: Cancelled | Q31: 46196 | R31: FHD-TRANSMIT-005778 | S31: _ | T31: _ | U31: _ | V31: _
A32: 730007 | B32: Cancelled | C32: XX | D32: 40-730007-4800001272-FHD-CIV-MAT-000021 | E32: 40-730007-4800001272-FHD-CIV-CRS-000024 | F32: 4800001272-FHD-CG - Material Submittal for Setseal AW309 Curing Compound by DCP Saudi Co. _ Supplier | G32: Material Submittal | H32: CIV - Civil | I32: B- Incorporate Comments - Proceed | J32: 45555 | K32: FHD-TRANSMIT-000032 | L32: =J32+7 -> 45562 | M32: 45561 | N32: =M32-L32 -> -1 | O32: WF-000251 | P32: Cancelled | Q32: 46196 | R32: FHD-TRANSMIT-005778 | S32: _ | T32: _ | U32: _ | V32: _
A33: 730007 | B33: A - Work May Proceed | C33: 02 | D33: 40-730007-4800001272-FHD-CIV-MAT-000022 | E33: 40-730007-4800001272-FHD-CIV-CRS-000025 | F33: 4800001272-FHD-CG - Material Submittal for Pest Control (Biflex TC) by Astrachem | G33: Material Submittal | H33: CIV - Civil | I33: B- Incorporate Comments - Proceed | J33: 45556 | K33: FHD-TRANSMIT-000034 | L33: =J33+7 -> 45563 | M33: 45563 | N33: =M33-L33 -> 0 | O33: WF-000252 | P33: A - Work May Proceed | Q33: 46205 | R33: FHD-TRANSMIT-005890 | S33: =Q33+7 -> 46212 | T33: 46215 | U33: =T33-S33 -> 3 | V33: WF-025842
A34: 730007 | B34: A - Work May Proceed | C34: 02 | D34: 40-730007-4800001272-FHD-CIV-MAT-000023 | E34: 40-730007-4800001272-FHD-CIV-CRS-000026 | F34: 4800001272-FHD-CG - Material Submittal for Sabit Plasto SPP Damp Proof Non-Fibrated Bitumen Emulsion & Ultimate Waterproofing Membrane+Protection Sheet by Unitech Isam Kabbani Co. | G34: Material Submittal | H34: CIV - Civil | I34: B- Incorporate Comments - Proceed | J34: 45561 | K34: FHD-TRANSMIT-000072 | L34: =J34+7 -> 45568 | M34: 45564 | N34: =M34-L34 -> -4 | O34: WF-000310 | P34: A - Work May Proceed | Q34: 46203 | R34: FHD-TRANSMIT-005871 | S34: =Q34+7 -> 46210 | T34: 46211 | U34: =T34-S34 -> 1 | V34: WF-026091
A35: 730007 | B35: A - Work May Proceed | C35: 02 | D35: 40-730007-4800001272-FHD-CIV-MAT-000024 | E35: 40-730007-4800001272-FHD-CIV-CRS-000031 | F35: 4800001272-FHD-CG - Material Submittal for Bertlandi SRC & OPC & BHC Cement by Tabuk Cement Company | G35: Material Submittal | H35: CIV - Civil | I35: B- Incorporate Comments - Proceed | J35: 45565 | K35: FHD-TRANSMIT-000094 | L35: =J35+7 -> 45572 | M35: 45567 | N35: =M35-L35 -> -5 | O35: WF-000337 | P35: A - Work May Proceed | Q35: 46204 | R35: FHD-TRANSMIT-005886 | S35: =Q35+7 -> 46211 | T35: 46215 | U35: =T35-S35 -> 4 | V35: WF-025841
A36: 730007 | B36: A - Work May Proceed | C36: 04 | D36: 40-730007-4800001272-FHD-CIV-MAT-000025 | E36: 40-730007-4800001272-FHD-CIV-CRS-000032 | F36: 4800001272-FHD-CG - Material Submittal for Concrete Design Mix For C16 MPA (SRC) by Soliman Bin Saleh Al-Mohileb Co. | G36: Material Submittal | H36: CIV - Civil | I36: B- Incorporate Comments - Proceed | J36: 45577 | K36: FHD-TRANSMIT-000143 | L36: =J36+7 -> 45584 | M36: 45579 | N36: =M36-L36 -> -5 | O36: WF-000453 | P36: B- Incorporate Comments - Proceed | Q36: 45776 | R36: FHD-TRANSMIT-001797 | S36: =Q36+7 -> 45783 | T36: 45784 | U36: =T36-S36 -> 1 | V36: WF-005797 | W36: B- Incorporate Comments - Proceed | X36: 45784 | Y36: FHD-TRANSMIT-001888 | Z36: =X36+7 -> 45791 | AA36: 45790 | AB36: =AA36-Z36 -> -1 | AC36: WF-006140 | AD36: A - Work May Proceed | AE36: 46194 | AF36: FHD-TRANSMIT-005757 | AG36: =AE36+7 -> 46201 | AH36: 46201 | AI36: =AH36-AG36 -> 0 | AJ36: WF-025224
A37: 730007 | B37: Cancelled | C37: XX | D37: 40-730007-4800001272-FHD-CIV-MAT-000026 | E37: 40-730007-4800001272-FHD-CIV-CRS-000033 | F37: 4800001272-FHD-CG - Material Submittal for Concrete Design Mix For C32 Mpa (OPC+65%GGBS + 8%MS) by Soliman Bin Saleh Al-Mohileb Co. | G37: Material Submittal | H37: CIV - Civil | I37: B- Incorporate Comments - Proceed | J37: 45577 | K37: FHD-TRANSMIT-000144 | L37: =J37+7 -> 45584 | M37: 45579 | N37: =M37-L37 -> -5 | O37: WF-000454 | P37: D - Rejected | Q37: 45776 | R37: FHD-TRANSMIT-001799 | S37: =Q37+7 -> 45783 | T37: 45784 | U37: =T37-S37 -> 1 | V37: WF-005798 | W37: Cancelled | X37: 46118 | Y37: FHD-TRANSMIT-004939 | Z37: _ | AA37: _ | AB37: _ | AC37: _
A38: 730007 | B38: Cancelled | C38: XX | D38: 40-730007-4800001272-FHD-CIV-MAT-000027 | E38: 40-730007-4800001272-FHD-CIV-CRS-000034 | F38: 4800001272-FHD-CG - Material Submittal for Concrete Design Mix For C40 Mpa (OPC+65%GGBS + 8%MS) + CI by Soliman Bin Saleh Al-Mohileb Co. | G38: Material Submittal | H38: CIV - Civil | I38: B- Incorporate Comments - Proceed | J38: 45571 | K38: FHD-TRANSMIT-000113 | L38: =J38+7 -> 45578 | M38: 45577 | N38: =M38-L38 -> -1 | O38: WF-000417 | P38: D - Rejected | Q38: 45776 | R38: FHD-TRANSMIT-001801 | S38: =Q38+7 -> 45783 | T38: 45784 | U38: =T38-S38 -> 1 | V38: WF-005799 | W38: Cancelled | X38: 46118 | Y38: FHD-TRANSMIT-004939 | Z38: _ | AA38: _ | AB38: _ | AC38: _
A39: 730007 | B39: A - Work May Proceed | C39: 02 | D39: 40-730007-4800001272-FHD-CIV-MAT-000028 | E39: 40-730007-4800001272-FHD-CIV-CRS-000046 | F39: 4800001272-FHD-CG - Material Submittal for Bitumen Impregnated Filler Board by Unitech for Building & Construction Materials | G39: Material Submittal | H39: CIV - Civil | I39: B- Incorporate Comments - Proceed | J39: 45586 | K39: FHD-TRANSMIT-000217 | L39: =J39+7 -> 45593 | M39: 45592 | N39: =M39-L39 -> -1 | O39: WF-000620 | P39: A - Work May Proceed | Q39: 46218 | S39: =Q39+7 -> 46225 | T39: 46229 | U39: =T39-S39 -> 4 | V39: WF-026523
A40: 730007 | B40: Cancelled | C40: XX | D40: 40-730007-4800001272-FHD-CIV-MAT-000029 | E40: 40-730007-4800001272-FHD-CIV-CRS-000047 | F40: 4800001272-FHD-CG - Material Submittal for Structural Steel Framing by Maani Steel | G40: Material Submittal | H40: CIV - Civil | I40: C - Revise and Resubmit - Do Not Proceed | J40: 45587 | K40: FHD-TRANSMIT-000224 | L40: =J40+7 -> 45594 | M40: 45589 | N40: =M40-L40 -> -5 | O40: WF-000655 | P40: C - Revise and Resubmit - Do Not Proceed | Q40: 45606 | R40: FHD-TRANSMIT-000382 | S40: =Q40+7 -> 45613 | T40: 45615 | U40: =T40-S40 -> 2 | V40: WF-001102 | W40: C - Revise and Resubmit - Do Not Proceed | X40: 45619 | Y40: FHD-TRANSMIT-000489 | Z40: =X40+7 -> 45626 | AA40: 45623 | AB40: =AA40-Z40 -> -3 | AC40: WF-001469 | AD40: Cancelled | AE40: 45824 | AF40: FHD-TRANSMIT-002165
A41: 730007 | B41: A - Work May Proceed | C41: 02 | D41: 40-730007-4800001272-FHD-CIV-MAT-000030 | E41: 40-730007-4800001272-FHD-CIV-CRS-000050 | F41: 4800001272-FHD-CG - Material Submittal for Cover Spacers Support by Isam Kabbani and Partners for Building and Construction Material | G41: Material Submittal | H41: CIV - Civil | I41: B- Incorporate Comments - Proceed | J41: 45589 | K41: FHD-TRANSMIT-000243 | L41: =J41+7 -> 45596 | M41: 45592 | N41: =M41-L41 -> -4 | O41: WF-000690 | P41: A - Work May Proceed | Q41: 46204 | R41: FHD-TRANSMIT-005884 | S41: =Q41+7 -> 46211 | T41: 46212 | U41: =T41-S41 -> 1 | V41: WF-025838
A42: 730007 | B42: A - Work May Proceed | C42: 01 | D42: 40-730007-4800001272-FHD-CIV-MAT-000031 | E42: 40-730007-4800001272-FHD-CIV-CRS-000053 | F42: 4800001272-FHD-CG - Material Submittal for Sika Igasol® Emulsion BA Rubberized Bituminous Waterproofing Emulsion by Color Diversity Decoration Co. | G42: Material Submittal | H42: CIV - Civil | I42: A - Work May Proceed | J42: 45600 | K42: FHD-TRANSMIT-000330 | L42: =J42+7 -> 45607 | M42: 45607 | N42: =M42-L42 -> 0 | O42: WF-000932
A43: 730007 | B43: A - Work May Proceed | C43: 01 | D43: 40-730007-4800001272-FHD-CIV-MAT-000032 | E43: 40-730007-4800001272-FHD-CIV-CRS-000054 | F43: 4800001272-FHD-CG - Material Submittal for Nitoproof 30 (Rubberised Bitumen Emulsion) by Fosam Company Limited | G43: Material Submittal | H43: CIV - Civil | I43: A - Work May Proceed | J43: 45602 | K43: FHD-TRANSMIT-000349 | L43: =J43+7 -> 45609 | M43: 45607 | N43: =M43-L43 -> -2 | O43: WF-000982
...

Sheet STR - MAT
B1: Contract Title: | C1: 4800001272-FHD-Construction of OXAGON Coast Guard Facilities | H1: Date: | I1: =TODAY() -> 46266
B2: Type of Doc: | C2: Material Submittal (MAT)
B3: Discipline: | C3: STR - Structural
B5: A - Work May Proceed | C5: B- Incorporate Comments - Proceed | D5: C - Revise and Resubmit - Do Not Proceed | E5: D - Rejected | F5: E - Review not Required - Proceed | G5: UR | H5: For Approval | I5: Terminated | J5: Cancelled
B6: =COUNTIF(B12:B34,"A - Work May Proceed") -> 13 | C6: =COUNTIF(B12:B34,"B- Incorporate Comments - Proceed") -> 5 | D6: =COUNTIF(B12:B34,"C - Revise and Resubmit - Do Not Proceed") -> 1 | E6: =COUNTIF(B12:B34,"D - Rejected") -> 0 | F6: =COUNTIF(B12:B34,"E - Review not Required - Proceed") -> 0 | G6: =COUNTIF(B12:B34,"UR") -> 0 | H6: =COUNTIF(B12:B34,"FA") -> 0 | I6: =COUNTIF(B12:B34,"Terminated") -> 0 | J6: =COUNTIF(B12:B34,"Cancelled") -> 3
B8: TOTAL | C8: =SUM(B6:J6) -> 22
A10: Asset Codes | B10: Current - Status | C10: Current - Revision | D10: ACONEX Document No | E10: Comments Resolution Sheet (CRS) | F10: Title | G10: Type | H10: Discipline | I10: Revision _ 01 - History | P10: Revision _ 02 - History | W10: Revision _ 03 - History | AD10: Revision _ 04 - History | AK10: Revision _ 05 - History | AR10: Revision _ 06 - History | AY10: Revision _ 07 - History | BF10: Internal notes
I11: Status | J11: Submission Date | K11: Al-Fahd Transmittal Reference | L11: Expected of Response | M11: Receiving Date | N11: Delay of Days | O11: Workflow Transmittal | P11: Status | Q11: Submission Date | R11: Al-Fahd Transmittal Reference | S11: Expected of Response | T11: Receiving Date | U11: Delay of Days | V11: Workflow Transmittal | W11: Status | X11: Submission Date | Y11: Al-Fahd Transmittal Reference | Z11: Expected of Response | AA11: Receiving Date | AB11: Delay of Days | AC11: Workflow Transmittal | AD11: Status | AE11: Submission Date | AF11: Al-Fahd Transmittal Reference | AG11: Expected of Response | AH11: Receiving Date | AI11: Delay of Days | AJ11: Workflow Transmittal | AK11: Status | AL11: Submission Date | AM11: Al-Fahd Transmittal Reference | AN11: Expected of Response | AO11: Receiving Date | AP11: Delay of Days | AQ11: Workflow Transmittal | AR11: Status | AS11: Submission Date | AT11: Al-Fahd Transmittal Reference | AU11: Expected of Response | AV11: Receiving Date | AW11: Delay of Days | AX11: Workflow Transmittal | AY11: Status | AZ11: Submission Date | BA11: Al-Fahd Transmittal Reference | BB11: Expected of Response | BC11: Receiving Date | BD11: Delay of Days | BE11: Workflow Transmittal
A12: 730007 | B12: A - Work May Proceed | C12: 04 | D12: 40-730007-4800001272-FHD-STR-MAT-000001 | E12: 40-730007-4800001272-FHD-STR-CRS-000007 | F12: 4800001272-FHD-CG - Material Submittal for Structural Steel Framing Manufactured By Maani (Hyundai Steel) | G12: Material Submittal | H12: STR - Structural | I12: B- Incorporate Comments - Proceed | J12: 45645 | K12: FHD-TRANSMIT-000766 | L12: =J12+7 -> 45652 | M12: 45654 | N12: =M12-L12 -> 2 | O12: WF-002181 | P12: B- Incorporate Comments - Proceed | Q12: 45777 | R12: FHD-TRANSMIT-001816 | S12: =Q12+7 -> 45784 | T12: 45788 | U12: =T12-S12 -> 4 | V12: WF-005904 | W12: B- Incorporate Comments - Proceed | X12: 45837 | Y12: FHD-TRANSMIT-002243 | Z12: =X12+7 -> 45844 | AA12: 45846 | AB12: =AA12-Z12 -> 2 | AC12: WF-008659 | AD12: A - Work May Proceed | AE12: 46229 | AF12: FHD-TRANSMIT-006121 | AG12: =AE12+7 -> 46236 | AH12: 46239 | AI12: =AH12-AG12 -> 3 | AJ12: WF-027180
A13: 730007 | B13: B- Incorporate Comments - Proceed | C13: 01 | D13: 40-730007-4800001272-FHD-STR-MAT-000002 | E13: 40-730007-4800001272-FHD-STR-CRS-000008 | F13: 4800001272-FHD-CG - Material Submittal for Handrails and Cage Access Ladder By Al Hadaf International Industries | G13: Material Submittal | H13: STR - Structural | I13: B- Incorporate Comments - Proceed | J13: 45650 | K13: FHD-TRANSMIT-000810 | L13: =J13+7 -> 45657 | M13: 45657 | N13: =M13-L13 -> 0 | O13: WF-002284
A14: 730007 | B14: C - Revise and Resubmit - Do Not Proceed | C14: 01 | D14: 40-730007-4800001272-FHD-STR-MAT-000003 | E14: 40-730007-4800001272-FHD-STR-CRS-000009 | F14: 4800001272-FHD-CG - Material Submittal for Fence and Gates By A One Fence Arabia Company Industry | G14: Material Submittal | H14: STR - Structural | I14: C - Revise and Resubmit - Do Not Proceed | J14: 45652 | K14: FHD-TRANSMIT-000838 | L14: =J14+7 -> 45659 | M14: 45697 | N14: =M14-L14 -> 38 | O14: WF-003122
A15: 730007 | B15: A - Work May Proceed | C15: 03 | D15: 40-730007-4800001272-FHD-STR-MAT-000004 | E15: 40-730007-4800001272-FHD-STR-CRS-000010 | F15: 4800001272-FHD-CG - Material Submittal for Intumescent Paint to Provide Fire Resistance to Steel Structure Elements By Maani - (Hempel Paint) | G15: Material Submittal | H15: STR - Structural | I15: B- Incorporate Comments - Proceed | J15: 45657 | K15: FHD-TRANSMIT-000875 | L15: =J15+7 -> 45664 | M15: 45680 | N15: =M15-L15 -> 16 | O15: WF-002726 | P15: B- Incorporate Comments - Proceed | Q15: 45755 | R15: FHD-TRANSMIT-001641 | S15: =Q15+7 -> 45762 | T15: 45760 | U15: =T15-S15 -> -2 | V15: WF-005105 | W15: A - Work May Proceed | X15: 46207 | Y15: FHD-TRANSMIT-005914 | Z15: =X15+7 -> 46214 | AA15: 46217 | AB15: =AA15-Z15 -> 3 | AC15: WF-025893
A16: 730007 | B16: A - Work May Proceed | C16: 05 | D16: 40-730007-4800001272-FHD-STR-MAT-000005 | E16: 40-730007-4800001272-FHD-STR-CRS-000011 | F16: 4800001272-FHD-CG - Material Submittal for Shear Studs By Maani (SWENN) | G16: Material Submittal | H16: STR - Structural | I16: C - Revise and Resubmit - Do Not Proceed | J16: 45664 | K16: FHD-TRANSMIT-000939 | L16: =J16+7 -> 45671 | M16: 45673 | N16: =M16-L16 -> 2 | O16: WF-002503 | P16: B- Incorporate Comments - Proceed | Q16: 45693 | R16: FHD-TRANSMIT-001209 | S16: =Q16+7 -> 45700 | T16: 45701 | U16: =T16-S16 -> 1 | V16: WF-003075 | W16: B- Incorporate Comments - Proceed | X16: 45777 | Y16: FHD-TRANSMIT-001814 | Z16: =X16+7 -> 45784 | AA16: 45788 | AB16: =AA16-Z16 -> 4 | AC16: WF-005905 | AD16: B- Incorporate Comments - Proceed | AE16: 45834 | AF16: FHD-TRANSMIT-002225 | AG16: =AE16+7 -> 45841 | AH16: 45844 | AI16: =AH16-AG16 -> 3 | AJ16: WF-008563 | AK16: A - Work May Proceed | AL16: 46215 | AM16: FHD-TRANSMIT-006007 | AN16: =AL16+7 -> 46222 | AO16: 46229 | AP16: =AO16-AN16 -> 7 | AQ16: WF-027011
A17: 730007 | B17: A - Work May Proceed | C17: 04 | D17: 40-730007-4800001272-FHD-STR-MAT-000006 | E17: 40-730007-4800001272-FHD-STR-CRS-000012 | F17: 4800001272-FHD-CG - Material Submittal for Structural Steel Framing By Maani (Emirates Steel) | G17: Material Submittal | H17: STR - Structural | I17: B- Incorporate Comments - Proceed | J17: 45664 | K17: FHD-TRANSMIT-000943 | L17: =J17+7 -> 45671 | M17: 45665 | N17: =M17-L17 -> -6 | O17: WF-002505 | P17: B- Incorporate Comments - Proceed | Q17: 45777 | R17: FHD-TRANSMIT-001813 | S17: =Q17+7 -> 45784 | T17: 45788 | U17: =T17-S17 -> 4 | V17: WF-005906 | W17: B- Incorporate Comments - Proceed | X17: 45833 | Y17: FHD-TRANSMIT-002224 | Z17: =X17+7 -> 45840 | AA17: 45844 | AB17: =AA17-Z17 -> 4 | AC17: WF-008564 | AD17: A - Work May Proceed | AE17: 46219 | AF17: FHD-TRANSMIT-006058 | AG17: =AE17+7 -> 46226 | AH17: 46229 | AI17: =AH17-AG17 -> 3 | AJ17: WF-026689
A18: 730007 | B18: B- Incorporate Comments - Proceed | C18: 02 | D18: 40-730007-4800001272-FHD-STR-MAT-000007 | E18: 40-730007-4800001272-FHD-STR-CRS-000013 | F18: 4800001272-FHD-CG - Material Submittal for Structural Steel Framing By Maani (THL TUBE & Pipe Industries LLC) | G18: Material Submittal | H18: STR - Structural | I18: B- Incorporate Comments - Proceed | J18: 45671 | K18: FHD-TRANSMIT-001004 | L18: =J18+7 -> 45678 | M18: 45673 | N18: =M18-L18 -> -5 | O18: WF-002600 | P18: B- Incorporate Comments - Proceed | Q18: 46235 | R18: FHD-TRANSMIT-006177 | S18: =Q18+7 -> 46242 | T18: 46245 | U18: =T18-S18 -> 3 | V18: WF-027500
A19: 730007 | B19: B- Incorporate Comments - Proceed | C19: 04 | D19: 40-730007-4800001272-FHD-STR-MAT-000008 | E19: 40-730007-4800001272-FHD-STR-CRS-000015 | F19: 4800001272-FHD-CG - Material Submittal for Structural Steel Framing By Maani (Sulb) | G19: Material Submittal | H19: STR - Structural | I19: B- Incorporate Comments - Proceed | J19: 45679 | K19: FHD-TRANSMIT-001081 | L19: =J19+7 -> 45686 | M19: 45686 | N19: =M19-L19 -> 0 | O19: WF-002874 | P19: B- Incorporate Comments - Proceed | Q19: 45777 | R19: FHD-TRANSMIT-001819 | S19: =Q19+7 -> 45784 | T19: 45788 | U19: =T19-S19 -> 4 | V19: WF-005907 | W19: B- Incorporate Comments - Proceed | X19: 45832 | Y19: FHD-TRANSMIT-002210 | Z19: =X19+7 -> 45839 | AA19: 45833 | AB19: =AA19-Z19 -> -6 | AC19: WF-008240 | AD19: B- Incorporate Comments - Proceed | AE19: 46235 | AF19: FHD-TRANSMIT-006176 | AG19: =AE19+7 -> 46242 | AH19: 46239 | AI19: =AH19-AG19 -> -3 | AJ19: WF-027502
A20: 730007 | B20: B- Incorporate Comments - Proceed | C20: 03 | D20: 40-730007-4800001272-FHD-STR-MAT-000009 | E20: 40-730007-4800001272-FHD-STR-CRS-000016 | F20: 4800001272-FHD-CG - Material Submittal for Structural Steel Framing By Maani Tianjin Yuantaiderun Pipe Manufacturing Group Co. Ltd. | G20: Material Submittal | H20: STR - Structural | I20: B- Incorporate Comments - Proceed | J20: 45679 | K20: FHD-TRANSMIT-001082 | L20: =J20+7 -> 45686 | M20: 45686 | N20: =M20-L20 -> 0 | O20: WF-002875 | P20: B- Incorporate Comments - Proceed | Q20: 45777 | R20: FHD-TRANSMIT-001820 | S20: =Q20+7 -> 45784 | T20: 45788 | U20: =T20-S20 -> 4 | V20: WF-005909 | W20: B- Incorporate Comments - Proceed | X20: 45832 | Y20: FHD-TRANSMIT-002212 | Z20: =X20+7 -> 45839 | AA20: 45837 | AB20: =AA20-Z20 -> -2 | AC20: WF-008342
A21: 730007 | B21: Cancelled | C21: XX | D21: 40-730007-4800001272-FHD-STR-MAT-000010 | E21: 40-730007-4800001272-FHD-STR-CRS-000018 | F21: 4800001272-FHD-CG - Material Submittal for Assembly Bolts, Washers and Nuts By Maani (Bright Star Construction Materials LLC) | G21: Material Submittal | H21: STR - Structural | I21: B- Incorporate Comments - Proceed | J21: 45706 | K21: FHD-TRANSMIT-001323 | L21: =J21+7 -> 45713 | M21: 45708 | N21: =M21-L21 -> -5 | O21: WF-003500 | P21: Cancelled | Q21: 46233 | R21: FHD-TRANSMIT-006157
A22: 730007 | B22: B- Incorporate Comments - Proceed | C22: 01 | D22: 40-730007-4800001272-FHD-STR-MAT-000011 | E22: 40-730007-4800001272-FHD-STR-CRS-000019 | F22: 4800001272-FHD-CG - Material Submittal for Assembly Bolts, Washers and Nuts By Maani (Asia Bolts Industries LLC) | G22: Material Submittal | H22: STR - Structural | I22: B- Incorporate Comments - Proceed | J22: 45706 | K22: FHD-TRANSMIT-001324 | L22: =J22+7 -> 45713 | M22: 45708 | N22: =M22-L22 -> -5 | O22: WF-003501
A23: 730007 | B23: A - Work May Proceed | C23: 2 | D23: 40-730007-4800001272-FHD-STR-MAT-000012 | E23: 40-730007-4800001272-FHD-STR-CRS-000020 | F23: 4800001272-FHD-CG - Material Submittal for 20mm Anchor Bolts By Masdar | G23: Material Submittal | H23: STR - Structural | I23: B- Incorporate Comments - Proceed | J23: 45786 | K23: FHD-TRANSMIT-001900 | L23: =J23+7 -> 45793 | M23: 45794 | N23: =M23-L23 -> 1 | O23: WF-006257 | P23: A - Work May Proceed | Q23: 46232 | R23: FHD-TRANSMIT-006142 | S23: =Q23+7 -> 46239 | T23: 46237 | U23: =T23-S23 -> -2 | V23: WF-027318
A24: 000000 | B24: Cancelled | C24: XX | D24: 40-000000-4800001272-FHD-STR-MAT-000001 | E24: 40-000000-4800001272-FHD-STR-CRS-000001 | F24: 4800001272-FHD-CG - Material Submittal for Primer Paint for Steel Structure By Maani - Jotun | G24: Material Submittal | H24: STR - Structural | I24: B- Incorporate Comments - Proceed | J24: 45860 | K24: FHD-TRANSMIT-002433 | L24: =J24+7 -> 45867 | M24: 45867 | N24: =M24-L24 -> 0 | O24: WF-010179 | P24: Cancelled | Q24: 46233 | R24: FHD-TRANSMIT-006157
A25: 000000 | B25: A - Work May Proceed | C25: 03 | D25: 40-000000-4800001272-FHD-STR-MAT-000002 | E25: 40-000000-4800001272-FHD-STR-CRS-000002 | F25: 4800001272-FHD-CG- Material Submittal for Sag Rod for Steel Structure By Maani - Masdar | G25: Material Submittal | H25: STR - Structural | I25: C - Revise and Resubmit - Do Not Proceed | J25: 45995 | K25: FHD-TRANSMIT-003701 | L25: =J25+7 -> 46002 | M25: 46004 | N25: =M25-L25 -> 2 | O25: WF-016244 | P25: B- Incorporate Comments - Proceed | Q25: 46018 | R25: FHD-TRANSMIT-003925 | S25: =Q25+7 -> 46025 | T25: 46020 | U25: =T25-S25 -> -5 | V25: WF-017348 | W25: A - Work May Proceed | X25: 46215 | Y25: FHD-TRANSMIT-006011 | Z25: =X25+7 -> 46222 | AA25: 46226 | AB25: =AA25-Z25 -> 4 | AC25: WF-026366
A26: 000000 | B26: A - Work May Proceed | C26: 01 | D26: 40-000000-4800001272-FHD-STR-MAT-000003 | E26: 40-000000-4800001272-FHD-STR-CRS-000003 | F26: 4800001272-FHD-CG- Material Submittal for Mechanical bolts for GRP Access hatch and access ladder by Masdar | G26: Material Submittal | H26: STR - Structural | I26: A - Work May Proceed | J26: 46011 | K26: FHD-TRANSMIT-003865 | L26: =J26+7 -> 46018 | M26: 46018 | N26: =M26-L26 -> 0 | O26: WF-017028
A27: 000000 | B27: A - Work May Proceed | C27: 03 | D27: 40-000000-4800001272-FHD-STR-MAT-000004 | E27: 40-000000-4800001272-FHD-STR-CRS-000004 | F27: 4800001272-FHD-CG - Material Submittal for Cladding Substructure By LAVENCO | G27: Material Submittal | H27: STR - Structural | I27: C - Revise and Resubmit - Do Not Proceed | J27: 46036 | K27: FHD-TRANSMIT-004080 | L27: =J27+7 -> 46043 | M27: 46046 | N27: =M27-L27 -> 3 | O27: WF-018127 | P27: C - Revise and Resubmit - Do Not Proceed | Q27: 46088 | R27: FHD-TRANSMIT-004628 | S27: =Q27+7 -> 46095 | T27: 46099 | U27: =T27-S27 -> 4 | V27: WF-020589 | W27: B- Incorporate Comments - Proceed | X27: 46114 | Y27: FHD-TRANSMIT-004888 | Z27: =X27+7 -> 46121 | AA27: 46119 | AB27: =AA27-Z27 -> -2 | AC27: WF-021605 | AD27: A - Work May Proceed | AE27: 46120 | AF27: FHD-TRANSMIT-004964 | AG27: =AE27+7 -> 46127 | AH27: 46123 | AI27: =AH27-AG27 -> -4 | AJ27: WF-021927
A28: 000000 | B28: Cancelled | C28: XX | D28: 40-000000-4800001272-FHD-STR-MAT-000005 | E28: 40-000000-4800001272-FHD-STR-CRS-000005 | F28: 4800001272-FHD-CG - Material Submittal For Shear Stud By Asia Bolts Industries Co / Maani. | G28: Material Submittal | H28: STR - Structural | I28: C - Revise and Resubmit - Do Not Proceed | J28: 46093 | K28: FHD-TRANSMIT-004689 | L28: =J28+7 -> 46100 | M28: 46109 | N28: =M28-L28 -> 9 | O28: WF-020853 | P28: Cancelled | Q28: 46233 | R28: FHD-TRANSMIT-006157
A29: 000000 | B29: A - Work May Proceed | C29: 03 | D29: 40-000000-4800001272-FHD-STR-MAT-000006 | E29: 40-000000-4800001272-FHD-STR-CRS-000006 | F29: 4800001272-FHD-CG - Material Submittal For Expansion Bolts By Maani (Hilti) | G29: Material Submittal | H29: STR - Structural | I29: C - Revise and Resubmit - Do Not Proceed | J29: 46111 | K29: FHD-TRANSMIT-004841 | L29: =J29+7 -> 46118 | M29: 46111 | N29: =M29-L29 -> -7 | O29: WF-021380 | P29: B- Incorporate Comments - Proceed | Q29: 46112 | R29: FHD-TRANSMIT-004855 | S29: =Q29+7 -> 46119 | T29: 46113 | U29: =T29-S29 -> -6 | V29: WF-021470 | W29: A - Work May Proceed | X29: 46208 | Y29: FHD-TRANSMIT-005926 | Z29: =X29+7 -> 46215 | AA29: 46216 | AB29: =AA29-Z29 -> 1 | AC29: WF-026156
A30: 000000 | B30: A - Work May Proceed | C30: 02 | D30: 40-000000-4800001272-FHD-STR-MAT-000007 | E30: 40-000000-4800001272-FHD-STR-CRS-000007 | F30: 4800001272-FHD-CG - Material Submittal For Chemical Anchors By Hilti | G30: Material Submittal | H30: STR - Structural | I30: B- Incorporate Comments - Proceed | J30: 46119 | K30: FHD-TRANSMIT-004952 | L30: =J30+7 -> 46126 | M30: 46124 | N30: =M30-L30 -> -2 | O30: WF-021862 | P30: A - Work May Proceed | Q30: 46133 | R30: FHD-TRANSMIT-005105 | S30: =Q30+7 -> 46140 | T30: 46134 | U30: =T30-S30 -> -6 | V30: WF-022561
A31: 000000 | B31: A - Work May Proceed | C31: 03 | D31: 40-000000-4800001272-FHD-STR-MAT-000008 | E31: 40-000000-4800001272-FHD-STR-CRS-000008 | F31: 4800001272-FHD-CG - Material Submittal For Anchor Bolts For Fire Pump By Masdar | G31: Material Submittal | H31: STR - Structural | I31: B- Incorporate Comments - Proceed | J31: 46125 | K31: FHD-TRANSMIT-005019 | L31: =J31+7 -> 46132 | M31: 46134 | N31: =M31-L31 -> 2 | O31: WF-022186 | P31: B- Incorporate Comments - Proceed | Q31: 46137 | R31: FHD-TRANSMIT-005162 | S31: =Q31+7 -> 46144 | T31: 46146 | U31: =T31-S31 -> 2 | V31: WF-022818 | W31: A - Work May Proceed | X31: 46151 | Y31: FHD-TRANSMIT-005376 | Z31: =X31+7 -> 46158 | AA31: 46152 | AB31: =AA31-Z31 -> -6 | AC31: WF-023499
A32: 000000 | B32: A - Work May Proceed | C32: 01 | D32: 40-000000-4800001272-FHD-STR-MAT-000009 | E32: 40-000000-4800001272-FHD-STR-CRS-000009 | F32: 4800001272-FHD-CG - Material Submittal For Steel Plates For 1st Floor Slab_Concrete Strengthening Works By Maani | G32: Material Submittal | H32: STR - Structural | I32: A - Work May Proceed | J32: 46162 | K32: FHD-TRANSMIT-005516 | L32: =J32+7 -> 46169 | M32: 46173 | N32: =M32-L32 -> 4 | O32: WF-024154
A33: 000000 | B33: A - Work May Proceed | C33: 01 | D33: 40-000000-4800001272-FHD-STR-MAT-000010 | E33: 40-000000-4800001272-FHD-STR-CRS-000010 | F33: 4800001272-FHD-CG-Material Submittal For Expansion Bolts for1 ST Floor Slab Strengthening Works By Maani (Hilti). | G33: Material Submittal | H33: STR - Structural | I33: A - Work May Proceed | J33: 46167 | K33: FHD-TRANSMIT-005580 | L33: =J33+7 -> 46174 | M33: 46173 | N33: =M33-L33 -> -1 | O33: WF-024322

Sheet ELE - MAT
B1: Contract Title: | C1: 4800001272-FHD-Construction of OXAGON Coast Guard Facilities | H1: Date: | I1: =TODAY() -> 46266
B2: Type of Doc: | C2: Material Submittal (MAT)
B3: Discipline: | C3: ELE - Electrical
B5: A - Work May Proceed | C5: B- Incorporate Comments - Proceed | D5: C - Revise and Resubmit - Do Not Proceed | E5: D - Rejected | F5: E - Review not Required - Proceed | G5: UR | H5: For Approval | I5: Terminated | J5: Cancelled
B6: =COUNTIF(B11:B72,"A - Work May Proceed") -> 34 | C6: =COUNTIF(B11:B72,"B- Incorporate Comments - Proceed") -> 2 | D6: =COUNTIF(B11:B72,"C - Revise and Resubmit - Do Not Proceed") -> 2 | E6: =COUNTIF(B11:B72,"D - Rejected") -> 0 | F6: =COUNTIF(B11:B72,"E - Review not Required - Proceed") -> 0 | G6: =COUNTIF(B11:B72,"UR") -> 1 | H6: =COUNTIF(B11:B72,"FA") -> 1 | I6: =COUNTIF(B11:B72,"Terminated") -> 0 | J6: =COUNTIF(B11:B72,"Cancelled") -> 21
B8: TOTAL | C8: =SUM(B6:J6) -> 61
A10: Asset Codes | B10: Current - Status | C10: Current - Revision | D10: ACONEX Document No | E10: Comments Resolution Sheet (CRS) | F10: Title | G10: Type | H10: Discipline | I10: Revision _ 01 - History | P10: Revision _ 02 - History | W10: Revision _ 03 - History | AD10: Revision _ 04 - History | AK10: Revision _ 05 - History | AR10: Revision _ 06 - History | AY10: Revision _ 07 - History | BF10: Revision _ 08 - History | BM10: Revision _ 09 - History | BT10: Revision _ 10 - History | CA10: Internal notes
I11: Status | J11: Submission Date | K11: Al-Fahd Transmittal Reference | L11: Expected of Response | M11: Receiving Date | N11: Delay of Days | O11: Workflow Transmittal | P11: Status | Q11: Submission Date | R11: Al-Fahd Transmittal Reference | S11: Expected of Response | T11: Receiving Date | U11: Delay of Days | V11: Workflow Transmittal | W11: Status | X11: Submission Date | Y11: Al-Fahd Transmittal Reference | Z11: Expected of Response | AA11: Receiving Date | AB11: Delay of Days | AC11: Workflow Transmittal | AD11: Status | AE11: Submission Date | AF11: Al-Fahd Transmittal Reference | AG11: Expected of Response | AH11: Receiving Date | AI11: Delay of Days | AJ11: Workflow Transmittal | AK11: Status | AL11: Submission Date | AM11: Al-Fahd Transmittal Reference | AN11: Expected of Response | AO11: Receiving Date | AP11: Delay of Days | AQ11: Workflow Transmittal | AR11: Status | AS11: Submission Date | AT11: Al-Fahd Transmittal Reference | AU11: Expected of Response | AV11: Receiving Date | AW11: Delay of Days | AX11: Workflow Transmittal | AY11: Status | AZ11: Submission Date | BA11: Al-Fahd Transmittal Reference | BB11: Expected of Response | BC11: Receiving Date | BD11: Delay of Days | BE11: Workflow Transmittal | BF11: Status | BG11: Submission Date | BH11: Al-Fahd Transmittal Reference | BI11: Expected of Response | BJ11: Receiving Date | BK11: Delay of Days | BL11: Workflow Transmittal | BM11: Status | BN11: Submission Date | BO11: Al-Fahd Transmittal Reference | BP11: Expected of Response | BQ11: Receiving Date | BR11: Delay of Days | BS11: Workflow Transmittal | BT11: Status | BU11: Submission Date | BV11: Al-Fahd Transmittal Reference | BW11: Expected of Response | BX11: Receiving Date | BY11: Delay of Days | BZ11: Workflow Transmittal
A12: 730007 | B12: A - Work May Proceed | C12: 02 | D12: 40-730007-4800001272-FHD-ELE-MAT-000001 | E12: 40-730007-4800001272-FHD-ELE-CRS-000006 | F12: 4800001272-FHD-CG - Material Submittal for Earthing and Lightning Protection Material By TEPCO | G12: Material Submittal | H12: ELE - Electrical | I12: B- Incorporate Comments - Proceed | J12: 45578 | K12: FHD-TRANSMIT-000150 | L12: =J12+7 -> 45585 | M12: 45581 | N12: =M12-L12 -> -4 | O12: WF-000465 | P12: A - Work May Proceed | Q12: 45706 | R12: FHD-TRANSMIT-001319 | S12: =Q12+7 -> 45713 | T12: 45719 | U12: =T12-S12 -> 6 | V12: WF-00349
A13: 730007 | B13: Cancelled | C13: XX | D13: 40-730007-4800001272-FHD-ELE-MAT-000002 | E13: 40-730007-4800001272-FHD-ELE-CRS-000007 | F13: 4800001272-FHD-CG - Material Submittal for UPVC Conduits and fittings by Bahra BC Conduit | G13: Material Submittal | H13: ELE - Electrical | I13: C - Revise and Resubmit - Do Not Proceed | J13: 45586 | K13: FHD-TRANSMIT-000212 | L13: =J13+7 -> 45593 | M13: 45592 | N13: =M13-L13 -> -1 | O13: WF-000601 | P13: Cancelled | Q13: 45652 | R13: FHD-TRANSMIT-000834 | S13: _ | T13: _ | U13: _ | V13: _
A14: 730007 | B14: Cancelled | C14: XX | D14: 40-730007-4800001272-FHD-ELE-MAT-000003 | E14: 40-730007-4800001272-FHD-ELE-CRS-000008 | F14: 4800001272-FHD-CG - Material Submittal for PVC Conduits and fittings by Bahra BC Conduit | G14: Material Submittal | H14: ELE - Electrical | I14: C - Revise and Resubmit - Do Not Proceed | J14: 45586 | K14: FHD-TRANSMIT-000213 | L14: =J14+7 -> 45593 | M14: 45592 | N14: =M14-L14 -> -1 | O14: WF-000602 | P14: Cancelled | Q14: 45652 | R14: FHD-TRANSMIT-000835 | S14: _ | T14: _ | U14: _ | V14: _
A15: 730007 | B15: Cancelled | C15: XX | D15: 40-730007-4800001272-FHD-ELE-MAT-000004 | E15: 40-730007-4800001272-FHD-ELE-CRS-000015 | F15: 4800001272-FHD-CG - Material Submittal for MV & LV Cables and Wires by Al Fahd Idahah Co - Bahra | G15: Material Submittal | H15: ELE - Electrical | I15: C - Revise and Resubmit - Do Not Proceed | J15: 45594 | K15: FHD-TRANSMIT-000274 | L15: =J15+7 -> 45601 | M15: 45598 | N15: =M15-L15 -> -3 | O15: WF-000773 | P15: Cancelled | Q15: 45652 | R15: FHD-TRANSMIT-000841 | S15: _ | T15: _ | U15: _ | V15: _
A16: 730007 | B16: Cancelled | C16: XX | D16: 40-730007-4800001272-FHD-ELE-MAT-000005 | E16: 40-730007-4800001272-FHD-ELE-CRS-000016 | F16: 4800001272-FHD-CG - Material Submittal for Lighting Control System and Sensors by Armada Solutions Company | G16: Material Submittal | H16: ELE - Electrical | I16: B- Incorporate Comments - Proceed | J16: 45598 | K16: FHD-TRANSMIT-000301 | L16: =J16+7 -> 45605 | M16: 45609 | N16: =M16-L16 -> 4 | O16: WF-000846 | P16: B- Incorporate Comments - Proceed | Q16: 45715 | R16: FHD-TRANSMIT-001393 | S16: =Q16+7 -> 45722 | T16: 45722 | U16: =T16-S16 -> 0 | V16: WF-003822 | W16: B- Incorporate Comments - Proceed | X16: 45783 | Y16: FHD-TRANSMIT-001876 | Z16: =X16+7 -> 45790 | AA16: 45798 | AB16: =AA16-Z16 -> 8 | AC16: WF-006131 / WF-006727 | AD16: Cancelled | AE16: 45878 | AF16: FHD-TRANSMIT-002574
